Workbook

Sheet birth to date
A1: 31922
A2: =NOW() -> 44562.365 | B2: =DATEDIF(A1,A2,"d") -> 12640

Sheet nasdaq 100
A1: week of year | B1: Weekday | C1: 日期 | D1: 收盘 | E1: 开盘 | F1: SMA5 | G1: SMA10 | H1: daily | I1: daily open | J1: daily - daily open | K1: go to SMA5 | L1: go to SMA10 | M1: compare to SMA5 | N1: compare to SMA10 | O1: SMA5 - SMA10 | P1: YTD | Q1: year over year | R1: week | T1: month | U1: go to 5 days before | V1: down 1% | W1: 5 days | X1: SMA5 5 days ago | Y1: go to SMA5*(1-0.01) | Z1: go to SMA5*(1-0.005) | AA1: daily down | AB1: daily up | AC1: EMA5 | AD1: EMA5(indice)
A2: =WEEKNUM(C2,2) -> 53 | B2: =WEEKDAY(C2,2) -> 5 | C2: 39080 | D2: 1756.9 | E2: 1759.15
A3: =WEEKNUM(C3,2) -> 1 | B3: =WEEKDAY(C3,2) -> 3 | C3: 39085 | D3: 1759.37 | E3: 1769.22 | H3: =(D3-D2)/D2 -> 0.0014058854 | I3: =(E3-D2)/D2 -> 0.0070123513 | J3: =H3-I3 -> -0.0056064659 | P3: =(D3-1756.9)/1756.9 -> 0.0014058854 | AA3: =(D3-D2)/D2 -> 0.0014058854 | AB3: =(D3-D2)/D2 -> 0.0014058854
A4: =WEEKNUM(C4,2) -> 1 | B4: =WEEKDAY(C4,2) -> 4 | C4: 39086 | D4: 1792.91 | E4: 1763.15 | H4: =(D4-D3)/D3 -> 0.019063642 | I4: =(E4-D3)/D3 -> 0.0021484963 | J4: =H4-I4 -> 0.016915146 | P4: =(D4-1756.9)/1756.9 -> 0.020496329 | AA4: =(D4-D3)/D3 -> 0.019063642 | AB4: =(D4-D3)/D3 -> 0.019063642
A5: =WEEKNUM(C5,2) -> 1 | B5: =WEEKDAY(C5,2) -> 5 | C5: 39087 | D5: 1785.3 | E5: 1787.79 | H5: =(D5-D4)/D4 -> -0.0042444964 | I5: =(E5-D4)/D4 -> -0.0028556927 | J5: =H5-I5 -> -0.0013888037 | P5: =(D5-1756.9)/1756.9 -> 0.016164836 | AA5: =(D5-D4)/D4 -> -0.0042444964 | AB5: =(D5-D4)/D4 -> -0.0042444964
A6: =WEEKNUM(C6,2) -> 2 | B6: =WEEKDAY(C6,2) -> 1 | C6: 39090 | D6: 1787.14 | E6: 1786.39 | F6: =AVERAGE(D2:D6) -> 1776.324 | H6: =(D6-D5)/D5 -> 0.0010306391 | I6: =(E6-D5)/D5 -> 0.00061054165 | J6: =H6-I6 -> 0.00042009746 | K6: =(SUM(D2:D5)/4-D5)/D5 -> -0.0065423178 | M6: =(D6-F6)/F6 -> 0.0060889793 | P6: =(D6-1756.9)/1756.9 -> 0.017212135 | Y6: =(SUM(D2:D5)*(0.99/4.01)-D5)/D5 -> -0.018929571 | Z6: =(SUM(D2:D5)*(0.995/4.005)-D5)/D5 -> -0.012743677 | AA6: =(D6-D5)/D5 -> 0.0010306391 | AB6: =(D6-D5)/D5 -> 0.0010306391
A7: =WEEKNUM(C7,2) -> 2 | B7: =WEEKDAY(C7,2) -> 2 | C7: 39091 | D7: 1795.63 | E7: 1791.75 | F7: =AVERAGE(D3:D7) -> 1784.07 | H7: =(D7-D6)/D6 -> 0.0047506071 | I7: =(E7-D6)/D6 -> 0.0025795405 | J7: =H7-I7 -> 0.0021710666 | K7: =(SUM(D3:D6)/4-D6)/D6 -> -0.0033349374 | M7: =(D7-F7)/F7 -> 0.0064795664 | P7: =(D7-1756.9)/1756.9 -> 0.02204451 | U7: =(D2-D6)/D6 -> -0.01692089 | V7: =(D2*(1-0.01)-D6)/D6 -> -0.026751681 | W7: =(D7-D2)/D2 -> 0.02204451 | Y7: =(SUM(D3:D6)*(0.99/4.01)-D6)/D6 -> -0.015762183 | Z7: =(SUM(D3:D6)*(0.995/4.005)-D6)/D6 -> -0.0095563173 | AA7: =(D7-D6)/D6 -> 0.0047506071 | AB7: =(D7-D6)/D6 -> 0.0047506071
A8: =WEEKNUM(C8,2) -> 2 | B8: =WEEKDAY(C8,2) -> 3 | C8: 39092 | D8: 1816.15 | E8: 1790.51 | F8: =AVERAGE(D4:D8) -> 1795.426 | H8: =(D8-D7)/D7 -> 0.011427744 | I8: =(E8-D7)/D7 -> -0.0028513669 | J8: =H8-I8 -> 0.014279111 | K8: =(SUM(D4:D7)/4-D7)/D7 -> -0.0029989474 | M8: =(D8-F8)/F8 -> 0.011542665 | P8: =(D8-1756.9)/1756.9 -> 0.033724173 | U8: =(D3-D7)/D7 -> -0.02019347 | V8: =(D3*(1-0.01)-D7)/D7 -> -0.029991535 | W8: =(D8-D3)/D3 -> 0.032272916 | Y8: =(SUM(D4:D7)*(0.99/4.01)-D7)/D7 -> -0.015430382 | Z8: =(SUM(D4:D7)*(0.995/4.005)-D7)/D7 -> -0.0092224247 | AA8: =(D8-D7)/D7 -> 0.011427744 | AB8: =(D8-D7)/D7 -> 0.011427744 | AC8: =(D8-AD8)/D8 -> 0.011775826 | AD8: =D8*(2/(5+1))+AVERAGE(D3:D7)*(1-(2/(5+1))) -> 1794.7633
A9: =WEEKNUM(C9,2) -> 2 | B9: =WEEKDAY(C9,2) -> 4 | C9: 39093 | D9: 1834.86 | E9: 1820.75 | F9: =AVERAGE(D5:D9) -> 1803.816 | H9: =(D9-D8)/D8 -> 0.010302012 | I9: =(E9-D8)/D8 -> 0.0025328304 | J9: =H9-I9 -> 0.0077691821 | K9: =(SUM(D5:D8)/4-D8)/D8 -> -0.011064615 | M9: =(D9-F9)/F9 -> 0.017210181 | P9: =(D9-1756.9)/1756.9 -> 0.044373613 | U9: =(D4-D8)/D8 -> -0.0127963 | V9: =(D4*(1-0.01)-D8)/D8 -> -0.022668337 | W9: =(D9-D4)/D4 -> 0.023397717 | Y9: =(SUM(D5:D8)*(0.99/4.01)-D8)/D8 -> -0.02339548 | Z9: =(SUM(D5:D8)*(0.995/4.005)-D8)/D8 -> -0.017237744 | AA9: =(D9-D8)/D8 -> 0.010302012 | AB9: =(D9-D8)/D8 -> 0.010302012 | AC9: =(D9-AD9)/D9 -> 0.014568474 | AD9: =D9*(2/(5+1))+AD8*(1-(2/(5+1))) -> 1808.1289
A10: =WEEKNUM(C10,2) -> 2 | B10: =WEEKDAY(C10,2) -> 5 | C10: 39094 | D10: 1844.81 | E10: 1832.15 | F10: =AVERAGE(D6:D10) -> 1815.718 | H10: =(D10-D9)/D9 -> 0.005422757 | I10: =(E10-D9)/D9 -> -0.0014769519 | J10: =H10-I10 -> 0.006899709 | K10: =(SUM(D6:D9)/4-D9)/D9 -> -0.014396194 | M10: =(D10-F10)/F10 -> 0.016022312 | P10: =(D10-1756.9)/1756.9 -> 0.050036997 | U10: =(D5-D9)/D9 -> -0.027010235 | V10: =(D5*(1-0.01)-D9)/D9 -> -0.036740133 | W10: =(D10-D5)/D5 -> 0.033333333 | Y10: =(SUM(D6:D9)*(0.99/4.01)-D9)/D9 -> -0.026685518 | Z10: =(SUM(D6:D9)*(0.995/4.005)-D9)/D9 -> -0.020548527 | AA10: =(D10-D9)/D9 -> 0.005422757 | AB10: =(D10-D9)/D9 -> 0.005422757 | AC10: =(D10-AD10)/D10 -> 0.013255606 | AD10: =D10*(2/(5+1))+AD9*(1-(2/(5+1))) -> 1820.3559
A11: =WEEKNUM(C11,2) -> 3 | B11: =WEEKDAY(C11,2) -> 2 | C11: 39098 | D11: 1842.44 | E11: 1844.73 | F11: =AVERAGE(D7:D11) -> 1826.778 | G11: =AVERAGE(D2:D11) -> 1801.551 | H11: =(D11-D10)/D10 -> -0.0012846851 | I11: =(E11-D10)/D10 -> -4.3364899e-05 | J11: =H11-I11 -> -0.0012413202 | K11: =(SUM(D7:D10)/4-D10)/D10 -> -0.011896889 | L11: =(SUM(D2:D10)/9-D10)/D10 -> -0.025911732 | M11: =(D11-F11)/F11 -> 0.008573565 | N11: =(D11-G11)/G11 -> 0.022696554 | O11: =(F11-G11)/D11 -> 0.013692169 | P11: =(D11-1756.9)/1756.9 -> 0.04868803 | U11: =(D6-D10)/D10 -> -0.031260672 | V11: =(D6*(1-0.01)-D10)/D10 -> -0.040948065 | W11: =(D11-D6)/D6 -> 0.030943295 | X11: =(F11-F6)/F6 -> 0.028403602 | Y11: =(SUM(D7:D10)*(0.99/4.01)-D10)/D10 -> -0.024217377 | Z11: =(SUM(D7:D10)*(0.995/4.005)-D10)/D10 -> -0.018064824 | AA11: =(D11-D10)/D10 -> -0.0012846851 | AB11: =(D11-D10)/D10 -> -0.0012846851 | AC11: =(D11-AD11)/D11 -> 0.0079908795 | AD11: =D11*(2/(5+1))+AD10*(1-(2/(5+1))) -> 1827.7173
A12: =WEEKNUM(C12,2) -> 3 | B12: =WEEKDAY(C12,2) -> 3 | C12: 39099 | D12: 1827.68 | E12: 1835.05 | F12: =AVERAGE(D8:D12) -> 1833.188 | G12: =AVERAGE(D3:D12) -> 1808.629 | H12: =(D12-D11)/D11 -> -0.0080111157 | I12: =(E12-D11)/D11 -> -0.0040109854 | J12: =H12-I12 -> -0.0040001303 | K12: =(SUM(D8:D11)/4-D11)/D11 -> -0.0042742233 | L12: =(SUM(D3:D11)/9-D11)/D11 -> -0.019500107 | M12: =(D12-F12)/F12 -> -0.0030046018 | N12: =(D12-G12)/G12 -> 0.010533393 | O12: =(F12-G12)/D12 -> 0.013437254 | P12: =(D12-1756.9)/1756.9 -> 0.040286869 | U12: =(D7-D11)/D11 -> -0.025406526 | V12: =(D7*(1-0.01)-D11)/D11 -> -0.035152461 | W12: =(D12-D7)/D7 -> 0.017848889 | X12: =(F12-F7)/F7 -> 0.027531431 | Y12: =(SUM(D8:D11)*(0.99/4.01)-D11)/D11 -> -0.016689757 | Z12: =(SUM(D8:D11)*(0.995/4.005)-D11)/D11 -> -0.01048974 | AA12: =(D12-D11)/D11 -> -0.0080111157 | AB12: =(D12-D11)/D11 -> -0.0080111157 | AC12: =(D12-AD12)/D12 -> -1.3599737e-05 | AD12: =D12*(2/(5+1))+AD11*(1-(2/(5+1))) -> 1827.7049
A13: =WEEKNUM(C13,2) -> 3 | B13: =WEEKDAY(C13,2) -> 4 | C13: 39100 | D13: 1793.68 | E13: 1821.99 | F13: =AVERAGE(D9:D13) -> 1828.694 | G13: =AVERAGE(D4:D13) -> 1812.06 | H13: =(D13-D12)/D12 -> -0.018602819 | I13: =(E13-D12)/D12 -> -0.0031132365 | J13: =H13-I13 -> -0.015489582 | K13: =(SUM(D9:D12)/4-D12)/D12 -> 0.0053442069 | L13: =(SUM(D4:D12)/9-D12)/D12 -> -0.0074289688 | M13: =(D13-F13)/F13 -> -0.019146998 | N13: =(D13-G13)/G13 -> -0.010143152 | O13: =(F13-G13)/D13 -> 0.009273672 | P13: =(D13-1756.9)/1756.9 -> 0.020934601 | U13: =(D8-D12)/D12 -> -0.0063085442 | V13: =(D8*(1-0.01)-D12)/D12 -> -0.016245459 | W13: =(D13-D8)/D8 -> -0.012372326 | X13: =(F13-F8)/F8 -> 0.018529307 | Y13: =(SUM(D9:D12)*(0.99/4.01)-D12)/D12 -> -0.0071912571 | Z13: =(SUM(D9:D12)*(0.995/4.005)-D12)/D12 -> -0.00093134998 | AA13: =(D13-D12)/D12 -> -0.018602819 | AB13: =(D13-D12)/D12 -> -0.018602819 | AC13: =(D13-AD13)/D13 -> -0.012646201 | AD13: =D13*(2/(5+1))+AD12*(1-(2/(5+1))) -> 1816.3632
A14: =WEEKNUM(C14,2) -> 3 | B14: =WEEKDAY(C14,2) -> 5 | C14: 39101 | D14: 1796.81 | E14: 1787.82 | F14: =AVERAGE(D10:D14) -> 1821.084 | G14: =AVERAGE(D5:D14) -> 1812.45 | H14: =(D14-D13)/D13 -> 0.0017450158 | I14: =(E14-D13)/D13 -> -0.0032670264 | J14: =H14-I14 -> 0.0050120423 | K14: =(SUM(D10:D13)/4-D13)/D13 -> 0.018661355 | L14: =(SUM(D5:D13)/9-D13)/D13 -> 0.011433354 | M14: =(D14-F14)/F14 -> -0.013329424 | N14: =(D14-G14)/G14 -> -0.0086292036 | O14: =(F14-G14)/D14 -> 0.0048051825 | P14: =(D14-1756.9)/1756.9 -> 0.022716148 | U14: =(D9-D13)/D13 -> 0.022958387 | V14: =(D9*(1-0.01)-D13)/D13 -> 0.012728803 | W14: =(D14-D9)/D9 -> -0.020737277 | X14: =(F14-F9)/F9 -> 0.0095730385 | Y14: =(SUM(D10:D13)*(0.99/4.01)-D13)/D13 -> 0.0059598423 | Z14: =(SUM(D10:D13)*(0.995/4.005)-D13)/D13 -> 0.01230267 | AA14: =(D14-D13)/D13 -> 0.0017450158 | AB14: =(D14-D13)/D13 -> 0.0017450158 | AC14: =(D14-AD14)/D14 -> -0.0072547969 | AD14: =D14*(2/(5+1))+AD13*(1-(2/(5+1))) -> 1809.8455
A15: =WEEKNUM(C15,2) -> 4 | B15: =WEEKDAY(C15,2) -> 1 | C15: 39104 | D15: 1779.02 | E15: 1800.33 | F15: =AVERAGE(D11:D15) -> 1807.926 | G15: =AVERAGE(D6:D15) -> 1811.822 | H15: =(D15-D14)/D14 -> -0.0099008799 | I15: =(E15-D14)/D14 -> 0.0019590274 | J15: =H15-I15 -> -0.011859907 | K15: =(SUM(D11:D14)/4-D14)/D14 -> 0.010208369 | L15: =(SUM(D6:D14)/9-D14)/D14 -> 0.010383216 | M15: =(D15-F15)/F15 -> -0.015988486 | N15: =(D15-G15)/G15 -> -0.018104427 | O15: =(F15-G15)/D15 -> -0.0021899698 | P15: =(D15-1756.9)/1756.9 -> 0.012590358 | U15: =(D10-D14)/D14 -> 0.02671401 | V15: =(D10*(1-0.01)-D14)/D14 -> 0.01644687 | W15: =(D15-D10)/D10 -> -0.035662209 | X15: =(F15-F10)/F10 -> -0.0042914153 | Y15: =(SUM(D11:D14)*(0.99/4.01)-D14)/D14 -> -0.0023877451 | Z15: =(SUM(D11:D14)*(0.995/4.005)-D14)/D14 -> 0.0039024494 | AA15: =(D15-D14)/D14 -> -0.0099008799 | AB15: =(D15-D14)/D14 -> -0.0099008799 | AC15: =(D15-AD15)/D15 -> -0.011551488 | AD15: =D15*(2/(5+1))+AD14*(1-(2/(5+1))) -> 1799.5703
A16: =WEEKNUM(C16,2) -> 4 | B16: =WEEKDAY(C16,2) -> 2 | C16: 39105 | D16: 1773.4 | E16: 1776.83 | F16: =AVERAGE(D12:D16) -> 1794.118 | G16: =AVERAGE(D7:D16) -> 1810.448 | H16: =(D16-D15)/D15 -> -0.0031590426 | I16: =(E16-D15)/D15 -> -0.0012310148 | J16: =H16-I16 -> -0.0019280278 | K16: =(SUM(D12:D15)/4-D15)/D15 -> 0.011398129 | L16: =(SUM(D7:D15)/9-D15)/D15 -> 0.019979789 | M16: =(D16-F16)/F16 -> -0.011547735 | N16: =(D16-G16)/G16 -> -0.020463443 | O16: =(F16-G16)/D16 -> -0.0092083004 | P16: =(D16-1756.9)/1756.9 -> 0.0093915419 | U16: =(D11-D15)/D15 -> 0.03564884 | V16: =(D11*(1-0.01)-D15)/D15 -> 0.025292352 | W16: =(D16-D11)/D11 -> -0.037472048 | X16: =(F16-F11)/F11 -> -0.017878472 | Y16: =(SUM(D12:D15)*(0.99/4.01)-D15)/D15 -> -0.0012128199 | Z16: =(SUM(D12:D15)*(0.995/4.005)-D15)/D15 -> 0.0050847827 | AA16: =(D16-D15)/D15 -> -0.0031590426 | AB16: =(D16-D15)/D15 -> -0.0031590426 | AC16: =(D16-AD16)/D16 -> -0.0098380992 | AD16: =D16*(2/(5+1))+AD15*(1-(2/(5+1))) -> 1790.8469
A17: =WEEKNUM(C17,2) -> 4 | B17: =WEEKDAY(C17,2) -> 3 | C17: 39106 | D17: 1802.63 | E17: 1785.42 | F17: =AVERAGE(D13:D17) -> 1789.108 | G17: =AVERAGE(D8:D17) -> 1811.148 | H17: =(D17-D16)/D16 -> 0.016482463 | I17: =(E17-D16)/D16 -> 0.0067779407 | J17: =H17-I17 -> 0.0097045224 | K17: =(SUM(D13:D16)/4-D16)/D16 -> 0.0069513364 | L17: =(SUM(D8:D16)/9-D16)/D16 -> 0.021819355 | M17: =(D17-F17)/F17 -> 0.0075579563 | N17: =(D17-G17)/G17 -> -0.0047030944 | O17: =(F17-G17)/D17 -> -0.01222658 | P17: =(D17-1756.9)/1756.9 -> 0.026028801 | U17: =(D12-D16)/D16 -> 0.030607872 | V17: =(D12*(1-0.01)-D16)/D16 -> 0.020301793 | W17: =(D17-D12)/D12 -> -0.0137059 | X17: =(F17-F12)/F12 -> -0.024045543 | Y17: =(SUM(D13:D16)*(0.99/4.01)-D16)/D16 -> -0.0056041665 | Z17: =(SUM(D13:D16)*(0.995/4.005)-D16)/D16 -> 0.00066574755 | AA17: =(D17-D16)/D16 -> 0.016482463 | AB17: =(D17-D16)/D16 -> 0.016482463 | AC17: =(D17-AD17)/D17 -> 0.0043577495 | AD17: =D17*(2/(5+1))+AD16*(1-(2/(5+1))) -> 1794.7746
A18: =WEEKNUM(C18,2) -> 4 | B18: =WEEKDAY(C18,2) -> 4 | C18: 39107 | D18: 1777.75 | E18: 1806.75 | F18: =AVERAGE(D14:D18) -> 1785.922 | G18: =AVERAGE(D9:D18) -> 1807.308 | H18: =(D18-D17)/D17 -> -0.013802056 | I18: =(E18-D17)/D17 -> 0.0022855494 | J18: =H18-I18 -> -0.016087605 | K18: =(SUM(D14:D17)/4-D17)/D17 -> -0.0081353356 | L18: =(SUM(D9:D17)/9-D17)/D17 -> 0.0044170031 | M18: =(D18-F18)/F18 -> -0.0045757877 | N18: =(D18-G18)/G18 -> -0.016354711 | O18: =(F18-G18)/D18 -> -0.012029813 | P18: =(D18-1756.9)/1756.9 -> 0.011867494 | U18: =(D13-D17)/D17 -> -0.0049649679 | V18: =(D13*(1-0.01)-D17)/D17 -> -0.014915318 | W18: =(D18-D13)/D13 -> -0.0088811828 | X18: =(F18-F13)/F13 -> -0.02338937 | Y18: =(SUM(D14:D17)*(0.99/4.01)-D17)/D17 -> -0.020502725 | Z18: =(SUM(D14:D17)*(0.995/4.005)-D17)/D17 -> -0.01432675 | AA18: =(D18-D17)/D17 -> -0.013802056 | AB18: =(D18-D17)/D17 -> -0.013802056 | AC18: =(D18-AD18)/D18 -> -0.006384321 | AD18: =D18*(2/(5+1))+AD17*(1-(2/(5+1))) -> 1789.0997
A19: =WEEKNUM(C19,2) -> 4 | B19: =WEEKDAY(C19,2) -> 5 | C19: 39108 | D19: 1772.97 | E19: 1783.38 | F19: =AVERAGE(D15:D19) -> 1781.154 | G19: =AVERAGE(D10:D19) -> 1801.119 | H19: =(D19-D18)/D18 -> -0.002688792 | I19: =(E19-D18)/D18 -> 0.0031669245 | J19: =H19-I19 -> -0.0058557165 | K19: =(SUM(D15:D18)/4-D18)/D18 -> 0.0030656729 | L19: =(SUM(D10:D18)/9-D18)/D18 -> 0.014904608 | M19: =(D19-F19)/F19 -> -0.0045947739 | N19: =(D19-G19)/G19 -> -0.015628618 | O19: =(F19-G19)/D19 -> -0.011260766 | P19: =(D19-1756.9)/1756.9 -> 0.0091467926 | U19: =(D14-D18)/D18 -> 0.010721418 | V19: =(D14*(1-0.01)-D18)/D18 -> 0.00061420335 | W19: =(D19-D14)/D14 -> -0.013267958 | X19: =(F19-F14)/F14 -> -0.021926501 | Y19: =(SUM(D15:D18)*(0.99/4.01)-D18)/D18 -> -0.0094413804 | Z19: =(SUM(D15:D18)*(0.995/4.005)-D18)/D18 -> -0.0031956609 | AA19: =(D19-D18)/D18 -> -0.002688792 | AB19: =(D19-D18)/D18 -> -0.002688792 | AC19: =(D19-AD19)/D19 -> -0.0060650497 | AD19: =D19*(2/(5+1))+AD18*(1-(2/(5+1))) -> 1783.7232
A20: =WEEKNUM(C20,2) -> 5 | B20: =WEEKDAY(C20,2) -> 1 | C20: 39111 | D20: 1775.08 | E20: 1771.05 | F20: =AVERAGE(D16:D20) -> 1780.366 | G20: =AVERAGE(D11:D20) -> 1794.146 | H20: =(D20-D19)/D19 -> 0.0011900935 | I20: =(E20-D19)/D19 -> -0.0010829286 | J20: =H20-I20 -> 0.0022730221 | K20: =(SUM(D16:D19)/4-D19)/D19 -> 0.0049168909 | L20: =(SUM(D11:D19)/9-D19)/D19 -> 0.013138657 | M20: =(D20-F20)/F20 -> -0.0029690524 | N20: =(D20-G20)/G20 -> -0.010626783 | O20: =(F20-G20)/D20 -> -0.0077630304 | P20: =(D20-1756.9)/1756.9 -> 0.010347772 | U20: =(D15-D19)/D19 -> 0.0034123533 | V20: =(D15*(1-0.01)-D19)/D19 -> -0.0066217702 | W20: =(D20-D15)/D15 -> -0.0022147025 | X20: =(F20-F15)/F15 -> -0.015243987 | Y20: =(SUM(D16:D19)*(0.99/4.01)-D19)/D19 -> -0.0076132449 | Z20: =(SUM(D16:D19)*(0.995/4.005)-D19)/D19 -> -0.0013559986 | AA20: =(D20-D19)/D19 -> 0.0011900935 | AB20: =(D20-D19)/D19 -> 0.0011900935 | AC20: =(D20-AD20)/D20 -> -0.0032461076 | AD20: =D20*(2/(5+1))+AD19*(1-(2/(5+1))) -> 1780.8421
A21: =WEEKNUM(C21,2) -> 5 | B21: =WEEKDAY(C21,2) -> 2 | C21: 39112 | D21: 1777.76 | E21: 1780.26 | F21: =AVERAGE(D17:D21) -> 1781.238 | G21: =AVERAGE(D12:D21) -> 1787.678 | H21: =(D21-D20)/D20 -> 0.0015097911 | I21: =(E21-D20)/D20 -> 0.0029181783 | J21: =H21-I21 -> -0.0014083872 | K21: =(SUM(D17:D20)/4-D20)/D20 -> 0.0039589765 | L21: =(SUM(D12:D20)/9-D20)/D20 -> 0.007717962 | M21: =(D21-F21)/F21 -> -0.0019525746 | N21: =(D21-G21)/G21 -> -0.005547979 | O21: =(F21-G21)/D21 -> -0.0036225362 | P21: =(D21-1756.9)/1756.9 -> 0.011873186 | U21: =(D16-D20)/D20 -> -0.00094643622 | V21: =(D16*(1-0.01)-D20)/D20 -> -0.010936972 | W21: =(D21-D16)/D16 -> 0.0024585542 | X21: =(F21-F16)/F16 -> -0.007179015 | Y21: =(SUM(D17:D20)*(0.99/4.01)-D20)/D20 -> -0.0085592152 | Z21: =(SUM(D17:D20)*(0.995/4.005)-D20)/D20 -> -0.0023079335 | AA21: =(D21-D20)/D20 -> 0.0015097911 | AB21: =(D21-D20)/D20 -> 0.0015097911 | AC21: =(D21-AD21)/D21 -> -0.0011557993 | AD21: =D21*(2/(5+1))+AD20*(1-(2/(5+1))) -> 1779.8147
A22: =WEEKNUM(C22,2) -> 5 | B22: =WEEKDAY(C22,2) -> 3 | C22: 39113 | D22: 1792.28 | E22: 1774.44 | F22: =AVERAGE(D18:D22) -> 1779.168 | G22: =AVERAGE(D13:D22) -> 1784.138 | H22: =(D22-D21)/D21 -> 0.0081675817 | I22: =(E22-D21)/D21 -> -0.0018675187 | J22: =H22-I22 -> 0.0100351 | K22: =(SUM(D18:D21)/4-D21)/D21 -> -0.0010518855 | L22: =(SUM(D13:D21)/9-D21)/D21 -> 0.0030787808 | M22: =(D22-F22)/F22 -> 0.0073697369 | N22: =(D22-G22)/G22 -> 0.0045635483 | O22: =(F22-G22)/D22 -> -0.0027730042 | P22: =(D22-1756.9)/1756.9 -> 0.020137743 | U22: =(D17-D21)/D21 -> 0.013989515 | V22: =(D17*(1-0.01)-D21)/D21 -> 0.0038496197 | W22: =(D22-D17)/D17 -> -0.0057416109 | X22: =(F22-F17)/F17 -> -0.0055558412 | Y22: =(SUM(D18:D21)*(0.99/4.01)-D21)/D21 -> -0.013507598 | Z22: =(SUM(D18:D21)*(0.995/4.005)-D21)/D21 -> -0.0072875167 | AA22: =(D22-D21)/D21 -> 0.0081675817 | AB22: =(D22-D21)/D21 -> 0.0081675817 | AC22: =(D22-AD22)/D22 -> 0.0046366513 | AD22: =D22*(2/(5+1))+AD21*(1-(2/(5+1))) -> 1783.9698
... A253: =WEEKNUM(C253,2) -> 53 | B253: =WEEKDAY(C253,2) -> 1 | C253: 39447 | D253: 2084.93 | E253: 2097.91 | F253: =AVERAGE(D249:D253) -> 2112.726 | G253: =AVERAGE(D244:D253) -> 2082.637 | H253: =(D253-D252)/D252 -> -0.01049809 | I253: =(E253-D252)/D252 -> -0.0043378183 | J253: =H253-I253 -> -0.0061602715 | K253: =(SUM(D249:D252)/4-D252)/D252 -> 0.0059917895 | L253: =(SUM(D244:D252)/9-D252)/D252 -> -0.011707258 | M253: =(D253-F253)/F253 -> -0.013156462 | N253: =(D253-G253)/G253 -> 0.001101008 | O253: =(F253-G253)/D253 -> 0.01443166 | P253: =(D253-1756.9)/1756.9 -> 0.18670955 | U253: =(D248-D252)/D252 -> 0.0022400987 | V253: =(D248*(1-0.01)-D252)/D252 -> -0.0077823023 | W253: =(D253-D248)/D248 -> -0.012709717 | X253: =(F253-F248)/F248 -> 0.029318681 | Y253: =(SUM(D249:D252)*(0.99/4.01)-D252)/D252 -> -0.0065517491 | Z253: =(SUM(D249:D252)*(0.995/4.005)-D252)/D252 -> -0.00028780972 | AA253: =(D253-D252)/D252 -> -0.01049809 | AB253: =(D253-D252)/D252 -> -0.01049809 | AC253: =(D253-AD253)/D253 -> -0.0069910697 | AD253: =D253*(2/(5+1))+AD252*(1-(2/(5+1))) -> 2099.5059
A254: =WEEKNUM(C254,2) -> 1 | B254: =WEEKDAY(C254,2) -> 3 | C254: 39449 | D254: 2049.71 | E254: 2085.53 | F254: =AVERAGE(D250:D254) -> 2096.944 | G254: =AVERAGE(D245:D254) -> 2085.528 | H254: =(D254-D253)/D253 -> -0.016892653 | I254: =(E254-D253)/D253 -> 0.00028777945 | J254: =H254-I254 -> -0.017180433 | K254: =(SUM(D250:D253)/4-D253)/D253 -> 0.011426043 | L254: =(SUM(D245:D253)/9-D253)/D253 -> 0.0021956506 | M254: =(D254-F254)/F254 -> -0.02252516 | N254: =(D254-G254)/G254 -> -0.017174548 | O254: =(F254-G254)/D254 -> 0.0055695684 | P254: =(D254-2084.93)/2084.93 -> -0.016892653 | U254: =(D249-D253)/D253 -> 0.02095514 | V254: =(D249*(1-0.01)-D253)/D253 -> 0.010745589 | W254: =(D254-D249)/D249 -> -0.037070966 | X254: =(F254-F249)/F249 -> 0.011008084 | Y254: =(SUM(D250:D253)*(0.99/4.01)-D253)/D253 -> -0.0011852542 | Z254: =(SUM(D250:D253)*(0.995/4.005)-D253)/D253 -> 0.0051125222 | AA254: =(D254-D253)/D253 -> -0.016892653 | AB254: =(D254-D253)/D253 -> -0.016892653 | AC254: =(D254-AD254)/D254 -> -0.016196077 | AD254: =D254*(2/(5+1))+AD253*(1-(2/(5+1))) -> 2082.9073
A255: =WEEKNUM(C255,2) -> 1 | B255: =WEEKDAY(C255,2) -> 4 | C255: 39450 | D255: 2051.76 | E255: 2050.64 | F255: =AVERAGE(D251:D255) -> 2079.908 | G255: =AVERAGE(D246:D255) -> 2087.755 | H255: =(D255-D254)/D254 -> 0.0010001415 | I255: =(E255-D254)/D254 -> 0.00045372272 | J255: =H255-I255 -> 0.00054641876 | K255: =(SUM(D251:D254)/4-D254)/D254 -> 0.018165984 | L255: =(SUM(D246:D254)/9-D254)/D254 -> 0.020512387 | M255: =(D255-F255)/F255 -> -0.013533291 | N255: =(D255-G255)/G255 -> -0.017241008 | O255: =(F255-G255)/D255 -> -0.0038245214 | P255: =(D255-2084.93)/2084.93 -> -0.015909407 | U255: =(D250-D254)/D254 -> 0.04255724 | V255: =(D250*(1-0.01)-D254)/D254 -> 0.032131667 | W255: =(D255-D250)/D250 -> -0.039860735 | X255: =(F255-F250)/F250 -> -0.0074890175 | Y255: =(SUM(D251:D254)*(0.99/4.01)-D254)/D254 -> 0.005470648 | Z255: =(SUM(D251:D254)*(0.995/4.005)-D254)/D254 -> 0.011810392 | AA255: =(D255-D254)/D254 -> 0.0010001415 | AB255: =(D255-D254)/D254 -> 0.0010001415 | AC255: =(D255-AD255)/D255 -> -0.010120502 | AD255: =D255*(2/(5+1))+AD254*(1-(2/(5+1))) -> 2072.5248
A256: =WEEKNUM(C256,2) -> 1 | B256: =WEEKDAY(C256,2) -> 5 | C256: 39451 | D256: 1963.52 | E256: 2025.36 | F256: =AVERAGE(D252:D256) -> 2051.394 | G256: =AVERAGE(D247:D256) -> 2081.007 | H256: =(D256-D255)/D255 -> -0.043006979 | I256: =(E256-D255)/D255 -> -0.012867002 | J256: =H256-I256 -> -0.030139977 | K256: =(SUM(D252:D255)/4-D255)/D255 -> 0.010528766 | L256: =(SUM(D247:D255)/9-D255)/D255 -> 0.020616988 | M256: =(D256-F256)/F256 -> -0.042836237 | N256: =(D256-G256)/G256 -> -0.056456802 | O256: =(F256-G256)/D256 -> -0.015081588 | P256: =(D256-2084.93)/2084.93 -> -0.058232171 | U256: =(D251-D255)/D255 -> 0.026479705 | V256: =(D251*(1-0.01)-D255)/D255 -> 0.016214908 | W256: =(D256-D251)/D251 -> -0.067694163 | X256: =(F256-F251)/F251 -> -0.028060949 | Y256: =(SUM(D252:D255)*(0.99/4.01)-D255)/D255 -> -0.0020713437 | Z256: =(SUM(D252:D255)*(0.995/4.005)-D255)/D255 -> 0.0042208457 | AA256: =(D256-D255)/D255 -> -0.043006979 | AB256: =(D256-D255)/D255 -> -0.043006979 | AC256: =(D256-AD256)/D256 -> -0.037010009 | AD256: =D256*(2/(5+1))+AD255*(1-(2/(5+1))) -> 2036.1899
A257: =WEEKNUM(C257,2) -> 2 | B257: =WEEKDAY(C257,2) -> 1 | C257: 39454 | D257: 1957.44 | E257: 1971.28 | F257: =AVERAGE(D253:D257) -> 2021.472 | G257: =AVERAGE(D248:D257) -> 2069.783 | H257: =(D257-D256)/D256 -> -0.0030964798 | I257: =(E257-D256)/D256 -> 0.003952086 | J257: =H257-I257 -> -0.0070485658 | K257: =(SUM(D253:D256)/4-D256)/D256 -> 0.037667047 | L257: =(SUM(D248:D256)/9-D256)/D256 -> 0.060475857 | M257: =(D257-F257)/F257 -> -0.031675927 | N257: =(D257-G257)/G257 -> -0.054277671 | O257: =(F257-G257)/D257 -> -0.024680705 | P257: =(D257-2084.93)/2084.93 -> -0.061148336 | U257: =(D252-D256)/D256 -> 0.073098313 | V257: =(D252*(1-0.01)-D256)/D256 -> 0.06236733 | W257: =(D257-D252)/D252 -> -0.071004485 | X257: =(F257-F252)/F252 -> -0.045617428 | Y257: =(SUM(D253:D256)*(0.99/4.01)-D256)/D256 -> 0.024728555 | Z257: =(SUM(D253:D256)*(0.995/4.005)-D256)/D256 -> 0.031189725 | AA257: =(D257-D256)/D256 -> -0.0030964798 | AB257: =(D257-D256)/D256 -> -0.0030964798 | AC257: =(D257-AD257)/D257 -> -0.026820709 | AD257: =D257*(2/(5+1))+AD256*(1-(2/(5+1))) -> 2009.9399
A258: =WEEKNUM(C258,2) -> 2 | B258: =WEEKDAY(C258,2) -> 2 | C258: 39455 | D258: 1910.33 | E258: 1965.42 | F258: =AVERAGE(D254:D258) -> 1986.552 | G258: =AVERAGE(D249:D258) -> 2049.639 | H258: =(D258-D257)/D257 -> -0.024067149 | I258: =(E258-D257)/D257 -> 0.0040767533 | J258: =H258-I258 -> -0.028143902 | K258: =(SUM(D254:D257)/4-D257)/D257 -> 0.024607395 | L258: =(SUM(D249:D257)/9-D257)/D257 -> 0.055009491 | M258: =(D258-F258)/F258 -> -0.038368993 | N258: =(D258-G258)/G258 -> -0.067967579 | O258: =(F258-G258)/D258 -> -0.033024137 | P258: =(D258-2084.93)/2084.93 -> -0.083743819 | U258: =(D253-D257)/D257 -> 0.065130987 | V258: =(D253*(1-0.01)-D257)/D257 -> 0.054479678 | W258: =(D258-D253)/D253 -> -0.083743819 | X258: =(F258-F253)/F253 -> -0.059720948 | Y258: =(SUM(D254:D257)*(0.99/4.01)-D257)/D257 -> 0.011831742 | Z258: =(SUM(D254:D257)*(0.995/4.005)-D257)/D257 -> 0.018211594 | AA258: =(D258-D257)/D257 -> -0.024067149 | AB258: =(D258-D257)/D257 -> -0.024067149 | AC258: =(D258-AD258)/D258 -> -0.034761858 | AD258: =D258*(2/(5+1))+AD257*(1-(2/(5+1))) -> 1976.7366
A259: =WEEKNUM(C259,2) -> 2 | B259: =WEEKDAY(C259,2) -> 3 | C259: 39456 | D259: 1949.2 | E259: 1915.23 | F259: =AVERAGE(D255:D259) -> 1966.45 | G259: =AVERAGE(D250:D259) -> 2031.697 | H259: =(D259-D258)/D258 -> 0.02034727 | I259: =(E259-D258)/D258 -> 0.0025650019 | J259: =H259-I259 -> 0.017782268 | K259: =(SUM(D255:D258)/4-D258)/D258 -> 0.031634587 | L259: =(SUM(D250:D258)/9-D258)/D258 -> 0.068330254 | M259: =(D259-F259)/F259 -> -0.0087721529 | N259: =(D259-G259)/G259 -> -0.040604972 | O259: =(F259-G259)/D259 -> -0.033473733 | P259: =(D259-2084.93)/2084.93 -> -0.065100507 | U259: =(D254-D258)/D258 -> 0.072961216 | V259: =(D254*(1-0.01)-D258)/D258 -> 0.062231604 | W259: =(D259-D254)/D254 -> -0.049036205 | X259: =(F259-F254)/F254 -> -0.06223056 | Y259: =(SUM(D255:D258)*(0.99/4.01)-D258)/D258 -> 0.018771313 | Z259: =(SUM(D255:D258)*(0.995/4.005)-D258)/D258 -> 0.02519492 | AA259: =(D259-D258)/D258 -> 0.02034727 | AB259: =(D259-D258)/D258 -> 0.02034727 | AC259: =(D259-AD259)/D259 -> -0.0094180927 | AD259: =D259*(2/(5+1))+AD258*(1-(2/(5+1))) -> 1967.5577
A260: =WEEKNUM(C260,2) -> 2 | B260: =WEEKDAY(C260,2) -> 4 | C260: 39457 | D260: 1953.64 | E260: 1930.91 | F260: =AVERAGE(D256:D260) -> 1946.826 | G260: =AVERAGE(D251:D260) -> 2013.367 | H260: =(D260-D259)/D259 -> 0.0022778576 | I260: =(E260-D259)/D259 -> -0.0093833368 | J260: =H260-I260 -> 0.011661194 | K260: =(SUM(D256:D259)/4-D259)/D259 -> -0.0020918838 | L260: =(SUM(D251:D259)/9-D259)/D259 -> 0.036324304 | M260: =(D260-F260)/F260 -> 0.003500056 | N260: =(D260-G260)/G260 -> -0.029665232 | O260: =(F260-G260)/D260 -> -0.034060011 | P260: =(D260-2084.93)/2084.93 -> -0.062970939 | U260: =(D255-D259)/D259 -> 0.052616458 | V260: =(D255*(1-0.01)-D259)/D259 -> 0.042090293 | W260: =(D260-D255)/D255 -> -0.047822357 | X260: =(F260-F255)/F255 -> -0.063984561 | Y260: =(SUM(D256:D259)*(0.99/4.01)-D259)/D259 -> -0.014534628 | Z260: =(SUM(D256:D259)*(0.995/4.005)-D259)/D259 -> -0.0083210232 | AA260: =(D260-D259)/D259 -> 0.0022778576 | AB260: =(D260-D259)/D259 -> 0.0022778576 | AC260: =(D260-AD260)/D260 -> -0.0047493384 | AD260: =D260*(2/(5+1))+AD259*(1-(2/(5+1))) -> 1962.9185
A261: =WEEKNUM(C261,2) -> 2 | B261: =WEEKDAY(C261,2) -> 5 | C261: 39458 | D261: 1912.81 | E261: 1940.98 | F261: =AVERAGE(D257:D261) -> 1936.684 | G261: =AVERAGE(D252:D261) -> 1994.039 | H261: =(D261-D260)/D260 -> -0.020899449 | I261: =(E261-D260)/D260 -> -0.0064802113 | J261: =H261-I261 -> -0.014419238 | K261: =(SUM(D257:D260)/4-D260)/D260 -> -0.005624117 | L261: =(SUM(D252:D260)/9-D260)/D260 -> 0.025298645 | M261: =(D261-F261)/F261 -> -0.012327256 | N261: =(D261-G261)/G261 -> -0.040735913 | O261: =(F261-G261)/D261 -> -0.029984682 | P261: =(D261-2084.93)/2084.93 -> -0.08255433 | U261: =(D256-D260)/D260 -> 0.0050572265 | V261: =(D256*(1-0.01)-D260)/D260 -> -0.0049933458 | W261: =(D261-D256)/D256 -> -0.025826067 | X261: =(F261-F256)/F256 -> -0.055918073 | Y261: =(SUM(D257:D260)*(0.99/4.01)-D260)/D260 -> -0.018022819 | Z261: =(SUM(D257:D260)*(0.995/4.005)-D260)/D260 -> -0.011831207 | AA261: =(D261-D260)/D260 -> -0.020899449 | AB261: =(D261-D260)/D260 -> -0.020899449 | AC261: =(D261-AD261)/D261 -> -0.017464184 | AD261: =D261*(2/(5+1))+AD260*(1-(2/(5+1))) -> 1946.2157
A262: =WEEKNUM(C262,2) -> 3 | B262: =WEEKDAY(C262,2) -> 1 | C262: 39461 | D262: 1949.15 | E262: 1940.33 | F262: =AVERAGE(D258:D262) -> 1935.026 | G262: =AVERAGE(D253:D262) -> 1978.249 | H262: =(D262-D261)/D261 -> 0.018998228 | I262: =(E262-D261)/D261 -> 0.01438721 | J262: =H262-I262 -> 0.0046110173 | K262: =(SUM(D258:D261)/4-D261)/D261 -> 0.0097683513 | L262: =(SUM(D253:D261)/9-D261)/D261 -> 0.035901225 | M262: =(D262-F262)/F262 -> 0.0072991267 | N262: =(D262-G262)/G262 -> -0.014709473 | O262: =(F262-G262)/D262 -> -0.022175307 | P262: =(D262-2084.93)/2084.93 -> -0.065124489 | U262: =(D257-D261)/D261 -> 0.023332166 | V262: =(D257*(1-0.01)-D261)/D261 -> 0.013098844 | W262: =(D262-D257)/D257 -> -0.0042351234 | X262: =(F262-F257)/F257 -> -0.042763887 | Y262: =(SUM(D258:D261)*(0.99/4.01)-D261)/D261 -> -0.0028222765 | Z262: =(SUM(D258:D261)*(0.995/4.005)-D261)/D261 -> 0.003465178 | AA262: =(D262-D261)/D261 -> 0.018998228 | AB262: =(D262-D261)/D261 -> 0.018998228 | AC262: =(D262-AD262)/D262 -> 0.0010036289 | AD262: =D262*(2/(5+1))+AD261*(1-(2/(5+1))) -> 1947.1938
A263: =WEEKNUM(C263,2) -> 3 | B263: =WEEKDAY(C263,2) -> 2 | C263: 39462 | D263: 1894.09 | E263: 1925.95 | F263: =AVERAGE(D259:D263) -> 1931.778 | G263: =AVERAGE(D254:D263) -> 1959.165 | H263: =(D263-D262)/D262 -> -0.028248211 | I263: =(E263-D262)/D262 -> -0.011902624 | J263: =H263-I263 -> -0.016345587 | K263: =(SUM(D259:D262)/4-D262)/D262 -> -0.004078701 | L263: =(SUM(D254:D262)/9-D262)/D262 -> 0.0088477313 | M263: =(D263-F263)/F263 -> -0.019509488 | N263: =(D263-G263)/G263 -> -0.033215681 | O263: =(F263-G263)/D263 -> -0.014459186 | P263: =(D263-2084.93)/2084.93 -> -0.091533049 | U263: =(D258-D262)/D262 -> -0.019916374 | V263: =(D258*(1-0.01)-D262)/D262 -> -0.02971721 | W263: =(D263-D258)/D258 -> -0.008501149 | X263: =(F263-F258)/F258 -> -0.027572397 | Y263: =(SUM(D259:D262)*(0.99/4.01)-D262)/D262 -> -0.016496672 | Z263: =(SUM(D259:D262)*(0.995/4.005)-D262)/D262 -> -0.010295438 | AA263: =(D263-D262)/D262 -> -0.028248211 | AB263: =(D263-D262)/D262 -> -0.028248211 | AC263: =(D263-AD263)/D263 -> -0.018691043 | AD263: =D263*(2/(5+1))+AD262*(1-(2/(5+1))) -> 1929.4925
A264: =WEEKNUM(C264,2) -> 3 | B264: =WEEKDAY(C264,2) -> 3 | C264: 39463 | D264: 1872.29 | E264: 1876.45 | F264: =AVERAGE(D260:D264) -> 1916.396 | G264: =AVERAGE(D255:D264) -> 1941.423 | H264: =(D264-D263)/D263 -> -0.011509485 | I264: =(E264-D263)/D263 -> -0.0093131794 | J264: =H264-I264 -> -0.0021963053 | K264: =(SUM(D260:D263)/4-D263)/D263 -> 0.017598161 | L264: =(SUM(D255:D263)/9-D263)/D263 -> 0.029045317 | M264: =(D264-F264)/F264 -> -0.023015076 | N264: =(D264-G264)/G264 -> -0.035609447 | O264: =(F264-G264)/D264 -> -0.013367053 | P264: =(D264-2084.93)/2084.93 -> -0.10198904 | U264: =(D259-D263)/D263 -> 0.029095766 | V264: =(D259*(1-0.01)-D263)/D263 -> 0.018804809 | W264: =(D264-D259)/D259 -> -0.039457213 | X264: =(F264-F259)/F259 -> -0.025453991 | Y264: =(SUM(D260:D263)*(0.99/4.01)-D263)/D263 -> 0.0049099042 | Z264: =(SUM(D260:D263)*(0.995/4.005)-D263)/D263 -> 0.011246112 | AA264: =(D264-D263)/D263 -> -0.011509485 | AB264: =(D264-D263)/D263 -> -0.011509485 | AC264: =(D264-AD264)/D264 -> -0.020368112 | AD264: =D264*(2/(5+1))+AD263*(1-(2/(5+1))) -> 1910.425
A265: =WEEKNUM(C265,2) -> 3 | B265: =WEEKDAY(C265,2) -> 4 | C265: 39464 | D265: 1842.1 | E265: 1882.36 | F265: =AVERAGE(D261:D265) -> 1894.088 | G265: =AVERAGE(D256:D265) -> 1920.457 | H265: =(D265-D264)/D264 -> -0.016124639 | I265: =(E265-D264)/D264 -> 0.0053784403 | J265: =H265-I265 -> -0.021503079 | K265: =(SUM(D261:D264)/4-D264)/D264 -> 0.018584194 | L265: =(SUM(D256:D264)/9-D264)/D264 -> 0.030376348 | M265: =(D265-F265)/F265 -> -0.02744751 | N265: =(D265-G265)/G265 -> -0.040801226 | O265: =(F265-G265)/D265 -> -0.014314641 | P265: =(D265-2084.93)/2084.93 -> -0.11646914 | U265: =(D260-D264)/D264 -> 0.043449466 | V265: =(D260*(1-0.01)-D264)/D264 -> 0.033014971 | W265: =(D265-D260)/D260 -> -0.057093426 | X265: =(F265-F260)/F260 -> -0.027089221 | Y265: =(SUM(D261:D264)*(0.99/4.01)-D264)/D264 -> 0.0058836426 | Z265: =(SUM(D261:D264)*(0.995/4.005)-D264)/D264 -> 0.01222599 | AA265: =(D265-D264)/D264 -> -0.016124639 | AB265: =(D265-D264)/D264 -> -0.016124639 | AC265: =(D265-AD265)/D265 -> -0.024727218 | AD265: =D265*(2/(5+1))+AD264*(1-(2/(5+1))) -> 1887.65
... A506: =WEEKNUM(C506,2) -> 53 | B506: =WEEKDAY(C506,2) -> 3 | C506: 39813 | D506: 1211.65 | E506: 1202.26 | F506: =AVERAGE(D502:D506) -> 1191.176 | G506: =AVERAGE(D497:D506) -> 1197.596 | H506: =(D506-D505)/D505 -> 0.0085820833 | I506: =(E506-D505)/D505 -> 0.00076581151 | J506: =H506-I506 -> 0.0078162718 | K506: =(SUM(D502:D505)/4-D505)/D505 -> -0.012721211 | L506: =(SUM(D497:D505)/9-D505)/D505 -> -0.0044163647 | M506: =(D506-F506)/F506 -> 0.017188056 | N506: =(D506-G506)/G506 -> 0.011735176 | O506: =(F506-G506)/D506 -> -0.0052985598 | P506: =(D506-2084.93)/2084.93 -> -0.41885339 | U506: =(D501-D505)/D505 -> -0.015108129 | V506: =(D501*(1-0.01)-D505)/D505 -> -0.024957048 | W506: =(D506-D501)/D501 -> 0.024053618 | X506: =(F506-F501)/F501 -> -0.01066431 | Y506: =(SUM(D502:D505)*(0.99/4.01)-D505)/D505 -> -0.025031421 | Z506: =(SUM(D502:D505)*(0.995/4.005)-D505)/D505 -> -0.018884 | AA506: =(D506-D505)/D505 -> 0.0085820833 | AB506: =(D506-D505)/D505 -> 0.0085820833 | AC506: =(D506-AD506)/D506 -> 0.011710183 | AD506: =D506*(2/(5+1))+AD505*(1-(2/(5+1))) -> 1197.4614
A507: =WEEKNUM(C507,2) -> 1 | B507: =WEEKDAY(C507,2) -> 5 | C507: 39815 | D507: 1263.7 | E507: 1212.74 | F507: =AVERAGE(D503:D507) -> 1207.056 | G507: =AVERAGE(D498:D507) -> 1201.38 | H507: =(D507-D506)/D506 -> 0.04295795 | I507: =(E507-D506)/D506 -> 0.00089959972 | J507: =H507-I507 -> 0.04205835 | K507: =(SUM(D503:D506)/4-D506)/D506 -> -0.015478892 | L507: =(SUM(D498:D506)/9-D506)/D506 -> -0.014190933 | M507: =(D507-F507)/F507 -> 0.0469274 | N507: =(D507-G507)/G507 -> 0.051873679 | O507: =(F507-G507)/D507 -> 0.0044915724 | P507: =(D507-1211.65)/1211.65 -> 0.04295795 | U507: =(D502-D506)/D506 -> -0.022572525 | V507: =(D502*(1-0.01)-D506)/D506 -> -0.0323468 | W507: =(D507-D502)/D502 -> 0.067043823 | X507: =(F507-F502)/F502 -> 0.0094939885 | Y507: =(SUM(D503:D506)*(0.99/4.01)-D506)/D506 -> -0.027754717 | Z507: =(SUM(D503:D506)*(0.995/4.005)-D506)/D506 -> -0.021624467 | AA507: =(D507-D506)/D506 -> 0.04295795 | AB507: =(D507-D506)/D506 -> 0.04295795 | AC507: =(D507-AD507)/D507 -> 0.034944287 | AD507: =D507*(2/(5+1))+AD506*(1-(2/(5+1))) -> 1219.5409
A508: =WEEKNUM(C508,2) -> 2 | B508: =WEEKDAY(C508,2) -> 1 | C508: 39818 | D508: 1262.52 | E508: 1254.7 | F508: =AVERAGE(D504:D508) -> 1222.472 | G508: =AVERAGE(D499:D508) -> 1207.163 | H508: =(D508-D507)/D507 -> -0.00093376593 | I508: =(E508-D507)/D507 -> -0.0071219435 | J508: =H508-I508 -> 0.0061881776 | K508: =(SUM(D504:D507)/4-D507)/D507 -> -0.040547598 | L508: =(SUM(D499:D507)/9-D507)/D507 -> -0.049606535 | M508: =(D508-F508)/F508 -> 0.032759851 | N508: =(D508-G508)/G508 -> 0.045857105 | O508: =(F508-G508)/D508 -> 0.012125749 | P508: =(D508-1211.65)/1211.65 -> 0.041984071 | U508: =(D503-D507)/D507 -> -0.061929255 | V508: =(D503*(1-0.01)-D507)/D507 -> -0.071309963 | W508: =(D508-D503)/D503 -> 0.06502227 | X508: =(F508-F503)/F503 -> 0.025689388 | Y508: =(SUM(D504:D507)*(0.99/4.01)-D507)/D507 -> -0.052510845 | Z508: =(SUM(D504:D507)*(0.995/4.005)-D507)/D507 -> -0.046536689 | AA508: =(D508-D507)/D507 -> -0.00093376593 | AB508: =(D508-D507)/D507 -> -0.00093376593 | AC508: =(D508-AD508)/D508 -> 0.022694873 | AD508: =D508*(2/(5+1))+AD507*(1-(2/(5+1))) -> 1233.8673
A509: =WEEKNUM(C509,2) -> 2 | B509: =WEEKDAY(C509,2) -> 2 | C509: 39819 | D509: 1274.49 | E509: 1274.36 | F509: =AVERAGE(D505:D509) -> 1242.74 | G509: =AVERAGE(D500:D509) -> 1212.893 | H509: =(D509-D508)/D508 -> 0.0094810379 | I509: =(E509-D508)/D508 -> 0.0093780693 | J509: =H509-I509 -> 0.00010296867 | K509: =(SUM(D505:D508)/4-D508)/D508 -> -0.021954108 | L509: =(SUM(D500:D508)/9-D508)/D508 -> -0.044728884 | M509: =(D509-F509)/F509 -> 0.025548385 | N509: =(D509-G509)/G509 -> 0.050785189 | O509: =(F509-G509)/D509 -> 0.023418779 | P509: =(D509-1211.65)/1211.65 -> 0.051863162 | U509: =(D504-D508)/D508 -> -0.070786997 | V509: =(D504*(1-0.01)-D508)/D508 -> -0.080079127 | W509: =(D509-D504)/D504 -> 0.086382815 | X509: =(F509-F504)/F504 -> 0.050457886 | Y509: =(SUM(D505:D508)*(0.99/4.01)-D508)/D508 -> -0.034149194 | Z509: =(SUM(D505:D508)*(0.995/4.005)-D508)/D508 -> -0.028059263 | AA509: =(D509-D508)/D508 -> 0.0094810379 | AB509: =(D509-D508)/D508 -> 0.0094810379 | AC509: =(D509-AD509)/D509 -> 0.021249143 | AD509: =D509*(2/(5+1))+AD508*(1-(2/(5+1))) -> 1247.4082
A510: =WEEKNUM(C510,2) -> 2 | B510: =WEEKDAY(C510,2) -> 3 | C510: 39820 | D510: 1238.6 | E510: 1249.98 | F510: =AVERAGE(D506:D510) -> 1250.192 | G510: =AVERAGE(D501:D510) -> 1217.838 | H510: =(D510-D509)/D509 -> -0.028160284 | I510: =(E510-D509)/D509 -> -0.019231222 | J510: =H510-I510 -> -0.0089290618 | K510: =(SUM(D506:D509)/4-D509)/D509 -> -0.01679103 | L510: =(SUM(D501:D509)/9-D509)/D509 -> -0.04626077 | M510: =(D510-F510)/F510 -> -0.0092721758 | N510: =(D510-G510)/G510 -> 0.017048245 | O510: =(F510-G510)/D510 -> 0.026121427 | P510: =(D510-1211.65)/1211.65 -> 0.022242397 | U510: =(D505-D509)/D509 -> -0.057395507 | V510: =(D505*(1-0.01)-D509)/D509 -> -0.066821552 | W510: =(D510-D505)/D505 -> 0.031015366 | X510: =(F510-F505)/F505 -> 0.054583613 | Y510: =(SUM(D506:D509)*(0.99/4.01)-D509)/D509 -> -0.029050494 | Z510: =(SUM(D506:D509)*(0.995/4.005)-D509)/D509 -> -0.022928414 | AA510: =(D510-D509)/D509 -> -0.028160284 | AB510: =(D510-D509)/D509 -> -0.028160284 | AC510: =(D510-AD510)/D510 -> -0.0047409331 | AD510: =D510*(2/(5+1))+AD509*(1-(2/(5+1))) -> 1244.4721
...

Sheet s&p 500
A1: week of year | B1: Weekday | C1: 日期 | D1: 收盘 | E1: 开盘 | F1: SMA5 | G1: SMA10 | H1: daily | I1: daily open | J1: daily - daily open | K1: go to SMA5 | L1: go to SMA10 | M1: compare to SMA5 | N1: compare to SMA10 | O1: SMA5 - SMA10 | P1: YTD | Q1: year over year | R1: week | S1: month | T1: daily down | U1: daily up | V1: go to 5 days before | W1: down 1% | X1: 5 days | Y1: go to SMA5*(1-0.01) | Z1: go to SMA5*(1-0.005) | AA1: SMA5 5 days before
A2: =WEEKNUM(C2,2) -> 53 | B2: =WEEKDAY(C2,2) -> 5 | C2: 39080 | D2: 1418.3 | E2: 1424.71
A3: =WEEKNUM(C3,2) -> 1 | B3: =WEEKDAY(C3,2) -> 3 | C3: 39085 | D3: 1416.6 | E3: 1418.03 | H3: =(D3-D2)/D2 -> -0.0011986181 | I3: =(E3-D2)/D2 -> -0.00019036875 | J3: =H3-I3 -> -0.0010082493 | P3: =(D3-1418.3)/1418.3 -> -0.0011986181 | T3: =(D3-D2)/D2 -> -0.0011986181 | U3: =(D3-D2)/D2 -> -0.0011986181
A4: =WEEKNUM(C4,2) -> 1 | B4: =WEEKDAY(C4,2) -> 4 | C4: 39086 | D4: 1418.34 | E4: 1416.6 | H4: =(D4-D3)/D3 -> 0.0012282931 | I4: =(E4-D3)/D3 -> 0 | J4: =H4-I4 -> 0.0012282931 | P4: =(D4-1418.3)/1418.3 -> 2.8202778e-05 | T4: =(D4-D3)/D3 -> 0.0012282931 | U4: =(D4-D3)/D3 -> 0.0012282931
A5: =WEEKNUM(C5,2) -> 1 | B5: =WEEKDAY(C5,2) -> 5 | C5: 39087 | D5: 1409.71 | E5: 1418.34 | H5: =(D5-D4)/D4 -> -0.0060845777 | I5: =(E5-D4)/D4 -> 0 | J5: =H5-I5 -> -0.0060845777 | P5: =(D5-1418.3)/1418.3 -> -0.0060565466 | T5: =(D5-D4)/D4 -> -0.0060845777 | U5: =(D5-D4)/D4 -> -0.0060845777
A6: =WEEKNUM(C6,2) -> 2 | B6: =WEEKDAY(C6,2) -> 1 | C6: 39090 | D6: 1412.84 | E6: 1409.26 | F6: =AVERAGE(D2:D6) -> 1415.158 | H6: =(D6-D5)/D5 -> 0.0022203148 | I6: =(E6-D5)/D5 -> -0.00031921459 | J6: =H6-I6 -> 0.0025395294 | K6: =(SUM(D2:D5)/4-D5)/D5 -> 0.0042757021 | M6: =(D6-F6)/F6 -> -0.0016379796 | P6: =(D6-1418.3)/1418.3 -> -0.0038496792 | T6: =(D6-D5)/D5 -> 0.0022203148 | U6: =(D6-D5)/D5 -> 0.0022203148 | Y6: =(SUM(D2:D5)*(0.99/4.01)-D5)/D5 -> -0.0082464388 | Z6: =(SUM(D2:D5)*(0.995/4.005)-D5)/D5 -> -0.0019931849
A7: =WEEKNUM(C7,2) -> 2 | B7: =WEEKDAY(C7,2) -> 2 | C7: 39091 | D7: 1412.11 | E7: 1412.84 | F7: =AVERAGE(D3:D7) -> 1413.92 | H7: =(D7-D6)/D6 -> -0.00051668979 | I7: =(E7-D6)/D6 -> 0 | J7: =H7-I7 -> -0.00051668979 | K7: =(SUM(D3:D6)/4-D6)/D6 -> 0.0010846947 | M7: =(D7-F7)/F7 -> -0.001280129 | P7: =(D7-1418.3)/1418.3 -> -0.0043643799 | T7: =(D7-D6)/D6 -> -0.00051668979 | U7: =(D7-D6)/D6 -> -0.00051668979 | V7: =(D2-D6)/D6 -> 0.0038645565 | W7: =(D2*(1-0.01)-D6)/D6 -> -0.0061740891 | X7: =(D7-D2)/D2 -> -0.0043643799 | Y7: =(SUM(D3:D6)*(0.99/4.01)-D6)/D6 -> -0.011397658 | Z7: =(SUM(D3:D6)*(0.995/4.005)-D6)/D6 -> -0.0051642735
A8: =WEEKNUM(C8,2) -> 2 | B8: =WEEKDAY(C8,2) -> 3 | C8: 39092 | D8: 1414.85 | E8: 1408.7 | F8: =AVERAGE(D4:D8) -> 1413.57 | H8: =(D8-D7)/D7 -> 0.0019403588 | I8: =(E8-D7)/D7 -> -0.002414826 | J8: =H8-I8 -> 0.0043551848 | K8: =(SUM(D4:D7)/4-D7)/D7 -> 0.00080730255 | M8: =(D8-F8)/F8 -> 0.00090550875 | P8: =(D8-1418.3)/1418.3 -> -0.0024324896 | T8: =(D8-D7)/D7 -> 0.0019403588 | U8: =(D8-D7)/D7 -> 0.0019403588 | V8: =(D3-D7)/D7 -> 0.003179639 | W8: =(D3*(1-0.01)-D7)/D7 -> -0.0068521574 | X8: =(D8-D3)/D3 -> -0.0012353523 | Y8: =(SUM(D4:D7)*(0.99/4.01)-D7)/D7 -> -0.011671591 | Z8: =(SUM(D4:D7)*(0.995/4.005)-D7)/D7 -> -0.005439934
A9: =WEEKNUM(C9,2) -> 2 | B9: =WEEKDAY(C9,2) -> 4 | C9: 39093 | D9: 1423.82 | E9: 1414.84 | F9: =AVERAGE(D5:D9) -> 1414.666 | H9: =(D9-D8)/D8 -> 0.0063398947 | I9: =(E9-D8)/D8 -> -7.0678871e-06 | J9: =H9-I9 -> 0.0063469626 | K9: =(SUM(D5:D8)/4-D8)/D8 -> -0.0017475351 | M9: =(D9-F9)/F9 -> 0.0064707853 | P9: =(D9-1418.3)/1418.3 -> 0.0038919834 | T9: =(D9-D8)/D8 -> 0.0063398947 | U9: =(D9-D8)/D8 -> 0.0063398947 | V9: =(D4-D8)/D8 -> 0.0024666926 | W9: =(D4*(1-0.01)-D8)/D8 -> -0.0075579743 | X9: =(D9-D4)/D4 -> 0.0038636716 | Y9: =(SUM(D5:D8)*(0.99/4.01)-D8)/D8 -> -0.014194573 | Z9: =(SUM(D5:D8)*(0.995/4.005)-D8)/D8 -> -0.0079788239
A10: =WEEKNUM(C10,2) -> 2 | B10: =WEEKDAY(C10,2) -> 5 | C10: 39094 | D10: 1430.73 | E10: 1423.82 | F10: =AVERAGE(D6:D10) -> 1418.87 | H10: =(D10-D9)/D9 -> 0.0048531415 | I10: =(E10-D9)/D9 -> 0 | J10: =H10-I10 -> 0.0048531415 | K10: =(SUM(D6:D9)/4-D9)/D9 -> -0.0055589892 | M10: =(D10-F10)/F10 -> 0.0083587644 | P10: =(D10-1418.3)/1418.3 -> 0.0087640133 | T10: =(D10-D9)/D9 -> 0.0048531415 | U10: =(D10-D9)/D9 -> 0.0048531415 | V10: =(D5-D9)/D9 -> -0.0099099605 | W10: =(D5*(1-0.01)-D9)/D9 -> -0.019810861 | X10: =(D10-D5)/D5 -> 0.014910868 | Y10: =(SUM(D6:D9)*(0.99/4.01)-D9)/D9 -> -0.017958503 | Z10: =(SUM(D6:D9)*(0.995/4.005)-D9)/D9 -> -0.011766486
A11: =WEEKNUM(C11,2) -> 3 | B11: =WEEKDAY(C11,2) -> 2 | C11: 39098 | D11: 1431.9 | E11: 1430.73 | F11: =AVERAGE(D7:D11) -> 1422.682 | G11: =AVERAGE(D2:D11) -> 1418.92 | H11: =(D11-D10)/D10 -> 0.00081776436 | I11: =(E11-D10)/D10 -> 0 | J11: =H11-I11 -> 0.00081776436 | K11: =(SUM(D7:D10)/4-D10)/D10 -> -0.0072358167 | L11: =(SUM(D2:D10)/9-D10)/D10 -> -0.0092625598 | M11: =(D11-F11)/F11 -> 0.0064793116 | N11: =(D11-G11)/G11 -> 0.0091478026 | O11: =(F11-G11)/D11 -> 0.0026272784 | P11: =(D11-1418.3)/1418.3 -> 0.0095889445 | T11: =(D11-D10)/D10 -> 0.00081776436 | U11: =(D11-D10)/D10 -> 0.00081776436 | V11: =(D6-D10)/D10 -> -0.012504106 | W11: =(D6*(1-0.01)-D10)/D10 -> -0.022379065 | X11: =(D11-D6)/D6 -> 0.013490558 | Y11: =(SUM(D7:D10)*(0.99/4.01)-D10)/D10 -> -0.019614422 | Z11: =(SUM(D7:D10)*(0.995/4.005)-D10)/D10 -> -0.013432847 | AA11: =(F11-F6)/F6 -> 0.0053167208
A12: =WEEKNUM(C12,2) -> 3 | B12: =WEEKDAY(C12,2) -> 3 | C12: 39099 | D12: 1430.62 | E12: 1431.77 | F12: =AVERAGE(D8:D12) -> 1426.384 | G12: =AVERAGE(D3:D12) -> 1420.152 | H12: =(D12-D11)/D11 -> -0.00089391717 | I12: =(E12-D11)/D11 -> -9.0788463e-05 | J12: =H12-I12 -> -0.00080312871 | K12: =(SUM(D8:D11)/4-D11)/D11 -> -0.0045918011 | L12: =(SUM(D3:D11)/9-D11)/D11 -> -0.0090167687 | M12: =(D12-F12)/F12 -> 0.0029697473 | N12: =(D12-G12)/G12 -> 0.007371042 | O12: =(F12-G12)/D12 -> 0.0043561533 | P12: =(D12-1418.3)/1418.3 -> 0.0086864556 | T12: =(D12-D11)/D11 -> -0.00089391717 | U12: =(D12-D11)/D11 -> -0.00089391717 | V12: =(D7-D11)/D11 -> -0.013820798 | W12: =(D7*(1-0.01)-D11)/D11 -> -0.02368259 | X12: =(D12-D7)/D7 -> 0.013108044 | Y12: =(SUM(D8:D11)*(0.99/4.01)-D11)/D11 -> -0.017003375 | Z12: =(SUM(D8:D11)*(0.995/4.005)-D11)/D11 -> -0.010805335 | AA12: =(F12-F7)/F7 -> 0.0088152088
A13: =WEEKNUM(C13,2) -> 3 | B13: =WEEKDAY(C13,2) -> 4 | C13: 39100 | D13: 1426.37 | E13: 1430.59 | F13: =AVERAGE(D9:D13) -> 1428.688 | G13: =AVERAGE(D4:D13) -> 1421.129 | H13: =(D13-D12)/D12 -> -0.00297074 | I13: =(E13-D12)/D12 -> -2.0969929e-05 | J13: =H13-I13 -> -0.00294977 | K13: =(SUM(D9:D12)/4-D12)/D12 -> -0.0009453943 | L13: =(SUM(D4:D12)/9-D12)/D12 -> -0.0070412362 | M13: =(D13-F13)/F13 -> -0.0016224676 | N13: =(D13-G13)/G13 -> 0.0036879129 | O13: =(F13-G13)/D13 -> 0.0052994665 | P13: =(D13-1418.3)/1418.3 -> 0.0056899105 | T13: =(D13-D12)/D12 -> -0.00297074 | U13: =(D13-D12)/D12 -> -0.00297074 | V13: =(D8-D12)/D12 -> -0.011023193 | W13: =(D8*(1-0.01)-D12)/D12 -> -0.020912961 | X13: =(D13-D8)/D8 -> 0.0081422059 | Y13: =(SUM(D9:D12)*(0.99/4.01)-D12)/D12 -> -0.013402434 | Z13: =(SUM(D9:D12)*(0.995/4.005)-D12)/D12 -> -0.0071816902 | AA13: =(F13-F8)/F8 -> 0.010694907
A14: =WEEKNUM(C14,2) -> 3 | B14: =WEEKDAY(C14,2) -> 5 | C14: 39101 | D14: 1430.5 | E14: 1426.35 | F14: =AVERAGE(D10:D14) -> 1430.024 | G14: =AVERAGE(D5:D14) -> 1422.345 | H14: =(D14-D13)/D13 -> 0.0028954619 | I14: =(E14-D13)/D13 -> -1.4021607e-05 | J14: =H14-I14 -> 0.0029094835 | K14: =(SUM(D10:D13)/4-D13)/D13 -> 0.0024783191 | L14: =(SUM(D5:D13)/9-D13)/D13 -> -0.0034571052 | M14: =(D14-F14)/F14 -> 0.00033286155 | N14: =(D14-G14)/G14 -> 0.0057334894 | O14: =(F14-G14)/D14 -> 0.0053680531 | P14: =(D14-1418.3)/1418.3 -> 0.0086018473 | T14: =(D14-D13)/D13 -> 0.0028954619 | U14: =(D14-D13)/D13 -> 0.0028954619 | V14: =(D9-D13)/D13 -> -0.0017877549 | W14: =(D9*(1-0.01)-D13)/D13 -> -0.011769877 | X14: =(D14-D9)/D9 -> 0.0046916043 | Y14: =(SUM(D10:D13)*(0.99/4.01)-D13)/D13 -> -0.010021411 | Z14: =(SUM(D10:D13)*(0.995/4.005)-D13)/D13 -> -0.0037793483 | AA14: =(F14-F9)/F9 -> 0.010856273
A15: =WEEKNUM(C15,2) -> 4 | B15: =WEEKDAY(C15,2) -> 1 | C15: 39104 | D15: 1422.95 | E15: 1430.47 | F15: =AVERAGE(D11:D15) -> 1428.468 | G15: =AVERAGE(D6:D15) -> 1423.669 | H15: =(D15-D14)/D14 -> -0.0052778749 | I15: =(E15-D14)/D14 -> -2.0971688e-05 | J15: =H15-I15 -> -0.0052569032 | K15: =(SUM(D11:D14)/4-D14)/D14 -> -0.00045613422 | L15: =(SUM(D6:D14)/9-D14)/D14 -> -0.0047194066 | M15: =(D15-F15)/F15 -> -0.0038628797 | N15: =(D15-G15)/G15 -> -0.00050503312 | O15: =(F15-G15)/D15 -> 0.0033725711 | P15: =(D15-1418.3)/1418.3 -> 0.0032785729 | T15: =(D15-D14)/D14 -> -0.0052778749 | U15: =(D15-D14)/D14 -> -0.0052778749 | V15: =(D10-D14)/D14 -> 0.00016078294 | W15: =(D10*(1-0.01)-D14)/D14 -> -0.0098408249 | X15: =(D15-D10)/D10 -> -0.0054377835 | Y15: =(SUM(D11:D14)*(0.99/4.01)-D14)/D14 -> -0.012919275 | Z15: =(SUM(D11:D14)*(0.995/4.005)-D14)/D14 -> -0.0066954842 | AA15: =(F15-F10)/F10 -> 0.006764538
A16: =WEEKNUM(C16,2) -> 4 | B16: =WEEKDAY(C16,2) -> 2 | C16: 39105 | D16: 1427.99 | E16: 1422.95 | F16: =AVERAGE(D12:D16) -> 1427.686 | G16: =AVERAGE(D7:D16) -> 1425.184 | H16: =(D16-D15)/D15 -> 0.0035419375 | I16: =(E16-D15)/D15 -> 0 | J16: =H16-I16 -> 0.0035419375 | K16: =(SUM(D12:D15)/4-D15)/D15 -> 0.0032748867 | L16: =(SUM(D7:D15)/9-D15)/D15 -> 0.0013508712 | M16: =(D16-F16)/F16 -> 0.00021293198 | N16: =(D16-G16)/G16 -> 0.0019688686 | O16: =(F16-G16)/D16 -> 0.0017521131 | P16: =(D16-1418.3)/1418.3 -> 0.006832123 | T16: =(D16-D15)/D15 -> 0.0035419375 | U16: =(D16-D15)/D15 -> 0.0035419375 | V16: =(D11-D15)/D15 -> 0.0062897502 | W16: =(D11*(1-0.01)-D15)/D15 -> -0.0037731473 | X16: =(D16-D11)/D11 -> -0.0027306376 | Y16: =(SUM(D12:D15)*(0.99/4.01)-D15)/D15 -> -0.0092347752 | Z16: =(SUM(D12:D15)*(0.995/4.005)-D15)/D15 -> -0.0029877531 | AA16: =(F16-F11)/F11 -> 0.0035173004
A17: =WEEKNUM(C17,2) -> 4 | B17: =WEEKDAY(C17,2) -> 3 | C17: 39106 | D17: 1440.13 | E17: 1427.96 | F17: =AVERAGE(D13:D17) -> 1429.588 | G17: =AVERAGE(D8:D17) -> 1427.986 | H17: =(D17-D16)/D16 -> 0.0085014601 | I17: =(E17-D16)/D16 -> -2.100855e-05 | J17: =H17-I17 -> 0.0085224686 | K17: =(SUM(D13:D16)/4-D16)/D16 -> -0.0007265457 | L17: =(SUM(D8:D16)/9-D16)/D16 -> -0.00094771905 | M17: =(D17-F17)/F17 -> 0.0073741526 | N17: =(D17-G17)/G17 -> 0.0085042851 | O17: =(F17-G17)/D17 -> 0.0011123996 | P17: =(D17-1418.3)/1418.3 -> 0.015391666 | T17: =(D17-D16)/D16 -> 0.0085014601 | U17: =(D17-D16)/D16 -> 0.0085014601 | V17: =(D12-D16)/D16 -> 0.0018417496 | W17: =(D12*(1-0.01)-D16)/D16 -> -0.0081766679 | X17: =(D17-D12)/D12 -> 0.0066474675 | Y17: =(SUM(D13:D16)*(0.99/4.01)-D16)/D16 -> -0.013186314 | Z17: =(SUM(D13:D16)*(0.995/4.005)-D16)/D16 -> -0.0069642077 | AA17: =(F17-F12)/F12 -> 0.0022462394
A18: =WEEKNUM(C18,2) -> 4 | B18: =WEEKDAY(C18,2) -> 4 | C18: 39107 | D18: 1423.9 | E18: 1440.12 | F18: =AVERAGE(D14:D18) -> 1429.094 | G18: =AVERAGE(D9:D18) -> 1428.891 | H18: =(D18-D17)/D17 -> -0.011269816 | I18: =(E18-D17)/D17 -> -6.9438176e-06 | J18: =H18-I18 -> -0.011262872 | K18: =(SUM(D14:D17)/4-D17)/D17 -> -0.0067615424 | L18: =(SUM(D9:D17)/9-D17)/D17 -> -0.0074190833 | M18: =(D18-F18)/F18 -> -0.0036344705 | N18: =(D18-G18)/G18 -> -0.0034929186 | O18: =(F18-G18)/D18 -> 0.00014256619 | P18: =(D18-1418.3)/1418.3 -> 0.0039483889 | T18: =(D18-D17)/D17 -> -0.011269816 | U18: =(D18-D17)/D17 -> -0.011269816 | V18: =(D13-D17)/D17 -> -0.009554693 | W18: =(D13*(1-0.01)-D17)/D17 -> -0.019459146 | X18: =(D18-D13)/D13 -> -0.0017316685 | Y18: =(SUM(D14:D17)*(0.99/4.01)-D17)/D17 -> -0.019146062 | Z18: =(SUM(D14:D17)*(0.995/4.005)-D17)/D17 -> -0.012961533 | AA18: =(F18-F13)/F13 -> 0.00028417681
A19: =WEEKNUM(C19,2) -> 4 | B19: =WEEKDAY(C19,2) -> 5 | C19: 39108 | D19: 1422.18 | E19: 1423.9 | F19: =AVERAGE(D15:D19) -> 1427.43 | G19: =AVERAGE(D10:D19) -> 1428.727 | H19: =(D19-D18)/D18 -> -0.00120795 | I19: =(E19-D18)/D18 -> 0 | J19: =H19-I19 -> -0.00120795 | K19: =(SUM(D15:D18)/4-D18)/D18 -> 0.0034008708 | L19: =(SUM(D10:D18)/9-D18)/D18 -> 0.0039008669 | M19: =(D19-F19)/F19 -> -0.0036779387 | N19: =(D19-G19)/G19 -> -0.004582401 | O19: =(F19-G19)/D19 -> -0.0009119802 | P19: =(D19-1418.3)/1418.3 -> 0.0027356695 | T19: =(D19-D18)/D18 -> -0.00120795 | U19: =(D19-D18)/D18 -> -0.00120795 | V19: =(D14-D18)/D18 -> 0.004635157 | W19: =(D14*(1-0.01)-D18)/D18 -> -0.0054111946 | X19: =(D19-D14)/D14 -> -0.0058161482 | Y19: =(SUM(D15:D18)*(0.99/4.01)-D18)/D18 -> -0.009110362 | Z19: =(SUM(D15:D18)*(0.995/4.005)-D18)/D18 -> -0.0028625553 | AA19: =(F19-F14)/F14 -> -0.0018139556
A20: =WEEKNUM(C20,2) -> 5 | B20: =WEEKDAY(C20,2) -> 1 | C20: 39111 | D20: 1420.62 | E20: 1422.03 | F20: =AVERAGE(D16:D20) -> 1426.964 | G20: =AVERAGE(D11:D20) -> 1427.716 | H20: =(D20-D19)/D19 -> -0.0010969076 | I20: =(E20-D19)/D19 -> -0.00010547188 | J20: =H20-I20 -> -0.00099143568 | K20: =(SUM(D16:D19)/4-D19)/D19 -> 0.0044790392 | L20: =(SUM(D11:D19)/9-D19)/D19 -> 0.004447007 | M20: =(D20-F20)/F20 -> -0.0044458024 | N20: =(D20-G20)/G20 -> -0.0049701761 | O20: =(F20-G20)/D20 -> -0.00052934634 | P20: =(D20-1418.3)/1418.3 -> 0.0016357611 | T20: =(D20-D19)/D19 -> -0.0010969076 | U20: =(D20-D19)/D19 -> -0.0010969076 | V20: =(D15-D19)/D19 -> 0.00054142232 | W20: =(D15*(1-0.01)-D19)/D19 -> -0.0094639919 | X20: =(D20-D15)/D15 -> -0.0016374433 | Y20: =(SUM(D16:D19)*(0.99/4.01)-D19)/D19 -> -0.0080456371 | Z20: =(SUM(D16:D19)*(0.995/4.005)-D19)/D19 -> -0.0017911171 | AA20: =(F20-F15)/F15 -> -0.0010528762
A21: =WEEKNUM(C21,2) -> 5 | B21: =WEEKDAY(C21,2) -> 2 | C21: 39112 | D21: 1428.82 | E21: 1420.61 | F21: =AVERAGE(D17:D21) -> 1427.13 | G21: =AVERAGE(D12:D21) -> 1427.408 | H21: =(D21-D20)/D20 -> 0.0057721277 | I21: =(E21-D20)/D20 -> -7.0391801e-06 | J21: =H21-I21 -> 0.0057791668 | K21: =(SUM(D17:D20)/4-D20)/D20 -> 0.0042851009 | L21: =(SUM(D12:D20)/9-D20)/D20 -> 0.0046677585 | M21: =(D21-F21)/F21 -> 0.0011841949 | N21: =(D21-G21)/G21 -> 0.00098920561 | O21: =(F21-G21)/D21 -> -0.00019456615 | P21: =(D21-1418.3)/1418.3 -> 0.0074173306 | T21: =(D21-D20)/D20 -> 0.0057721277 | U21: =(D21-D20)/D20 -> 0.0057721277 | V21: =(D16-D20)/D20 -> 0.0051878757 | W21: =(D16*(1-0.01)-D20)/D20 -> -0.004864003 | X21: =(D21-D16)/D16 -> 0.00058123656 | Y21: =(SUM(D17:D20)*(0.99/4.01)-D20)/D20 -> -0.0082371572 | Z21: =(SUM(D17:D20)*(0.995/4.005)-D20)/D20 -> -0.0019838448 | AA21: =(F21-F16)/F16 -> -0.00038944138
A22: =WEEKNUM(C22,2) -> 5 | B22: =WEEKDAY(C22,2) -> 3 | C22: 39113 | D22: 1438.24 | E22: 1428.65 | F22: =AVERAGE(D18:D22) -> 1426.752 | G22: =AVERAGE(D13:D22) -> 1428.17 | H22: =(D22-D21)/D21 -> 0.0065928528 | I22: =(E22-D21)/D21 -> -0.0001189793 | J22: =H22-I22 -> 0.0067118321 | K22: =(SUM(D18:D21)/4-D21)/D21 -> -0.0034573984 | L22: =(SUM(D13:D21)/9-D21)/D21 -> -0.0012380068 | M22: =(D22-F22)/F22 -> 0.0080518548 | N22: =(D22-G22)/G22 -> 0.0070509813 | O22: =(F22-G22)/D22 -> -0.00098592724 | P22: =(D22-1418.3)/1418.3 -> 0.014059085 | T22: =(D22-D21)/D21 -> 0.0065928528 | U22: =(D22-D21)/D21 -> 0.0065928528 | V22: =(D17-D21)/D21 -> 0.0079156227 | W22: =(D17*(1-0.01)-D21)/D21 -> -0.0021635335 | X22: =(D22-D17)/D17 -> -0.0013123815 | Y22: =(SUM(D18:D21)*(0.99/4.01)-D21)/D21 -> -0.015883117 | Z22: =(SUM(D18:D21)*(0.995/4.005)-D21)/D21 -> -0.0096780139 | AA22: =(F22-F17)/F17 -> -0.0019837883
... A252: =WEEKNUM(C252,2) -> 53 | B252: =WEEKDAY(C252,2) -> 1 | C252: 39447 | D252: 1468.36 | E252: 1475.25 | F252: =AVERAGE(D248:D252) -> 1483.446 | G252: =AVERAGE(D243:D252) -> 1471.569 | H252: =(D252-D251)/D251 -> -0.0068515851 | I252: =(E252-D251)/D251 -> -0.002191425 | J252: =H252-I252 -> -0.00466016 | K252: =(SUM(D248:D251)/4-D251)/D251 -> 0.0059029821 | L252: =(SUM(D243:D251)/9-D251)/D251 -> -0.0044399654 | M252: =(D252-F252)/F252 -> -0.010169565 | N252: =(D252-G252)/G252 -> -0.0021806657 | O252: =(F252-G252)/D252 -> 0.0080886159 | P252: =(D252-1418.3)/1418.3 -> 0.035295777 | T252: =(D252-D251)/D251 -> -0.0068515851 | U252: =(D252-D251)/D251 -> -0.0068515851 | V252: =(D247-D251)/D251 -> 0.0040379035 | W252: =(D247*(1-0.01)-D251)/D251 -> -0.0060024755 | X252: =(D252-D247)/D247 -> -0.010845695 | Y252: =(SUM(D248:D251)*(0.99/4.01)-D251)/D251 -> -0.0066394491 | Z252: =(SUM(D248:D251)*(0.995/4.005)-D251)/D251 -> -0.00037606274 | AA252: =(F252-F247)/F247 -> 0.016273296
A253: =WEEKNUM(C253,2) -> 1 | B253: =WEEKDAY(C253,2) -> 3 | C253: 39449 | D253: 1447.16 | E253: 1467.97 | F253: =AVERAGE(D249:D253) -> 1473.588 | G253: =AVERAGE(D244:D253) -> 1471.695 | H253: =(D253-D252)/D252 -> -0.014437876 | I253: =(E253-D252)/D252 -> -0.00026560244 | J253: =H253-I253 -> -0.014172274 | K253: =(SUM(D249:D252)/4-D252)/D252 -> 0.0080600125 | L253: =(SUM(D244:D252)/9-D252)/D252 -> 0.00412781 | M253: =(D253-F253)/F253 -> -0.017934457 | N253: =(D253-G253)/G253 -> -0.016671253 | O253: =(F253-G253)/D253 -> 0.0013080793 | P253: =(D253-1468.36)/1468.36 -> -0.014437876 | T253: =(D253-D252)/D252 -> -0.014437876 | U253: =(D253-D252)/D252 -> -0.014437876 | V253: =(D248-D252)/D252 -> 0.019130186 | W253: =(D248*(1-0.01)-D252)/D252 -> 0.0089388842 | X253: =(D253-D248)/D248 -> -0.032937953 | Y253: =(SUM(D249:D252)*(0.99/4.01)-D252)/D252 -> -0.0045093143 | Z253: =(SUM(D249:D252)*(0.995/4.005)-D252)/D252 -> 0.0017675031 | AA253: =(F253-F248)/F248 -> 0.0025758572
A254: =WEEKNUM(C254,2) -> 1 | B254: =WEEKDAY(C254,2) -> 4 | C254: 39450 | D254: 1447.16 | E254: 1447.55 | F254: =AVERAGE(D250:D254) -> 1463.488 | G254: =AVERAGE(D245:D254) -> 1470.913 | H254: =(D254-D253)/D253 -> 0 | I254: =(E254-D253)/D253 -> 0.00026949335 | J254: =H254-I254 -> -0.00026949335 | K254: =(SUM(D250:D253)/4-D253)/D253 -> 0.014103485 | L254: =(SUM(D245:D253)/9-D253)/D253 -> 0.018237252 | M254: =(D254-F254)/F254 -> -0.011156907 | N254: =(D254-G254)/G254 -> -0.016148474 | O254: =(F254-G254)/D254 -> -0.0051307388 | P254: =(D254-1468.36)/1468.36 -> -0.014437876 | T254: =(D254-D253)/D253 -> 0 | U254: =(D254-D253)/D253 -> 0 | V254: =(D249-D253)/D253 -> 0.034895934 | W254: =(D249*(1-0.01)-D253)/D253 -> 0.024546975 | X254: =(D254-D249)/D249 -> -0.033719269 | Y254: =(SUM(D250:D253)*(0.99/4.01)-D253)/D253 -> 0.0014588036 | Z254: =(SUM(D250:D253)*(0.995/4.005)-D253)/D253 -> 0.0077732515 | AA254: =(F254-F249)/F249 -> -0.010045064
A255: =WEEKNUM(C255,2) -> 1 | B255: =WEEKDAY(C255,2) -> 5 | C255: 39451 | D255: 1411.63 | E255: 1444.01 | F255: =AVERAGE(D251:D255) -> 1450.56 | G255: =AVERAGE(D246:D255) -> 1466.776 | H255: =(D255-D254)/D254 -> -0.024551535 | I255: =(E255-D254)/D254 -> -0.0021766771 | J255: =H255-I255 -> -0.022374858 | K255: =(SUM(D251:D254)/4-D254)/D254 -> 0.0090746704 | L255: =(SUM(D246:D254)/9-D254)/D254 -> 0.017788865 | M255: =(D255-F255)/F255 -> -0.026837911 | N255: =(D255-G255)/G255 -> -0.037596743 | O255: =(F255-G255)/D255 -> -0.011487429 | P255: =(D255-1468.36)/1468.36 -> -0.03863494 | T255: =(D255-D254)/D254 -> -0.024551535 | U255: =(D255-D254)/D254 -> -0.024551535 | V255: =(D250-D254)/D254 -> 0.02011526 | W255: =(D250*(1-0.01)-D254)/D254 -> 0.0099141076 | X255: =(D255-D250)/D250 -> -0.043786028 | Y255: =(SUM(D251:D254)*(0.99/4.01)-D254)/D254 -> -0.003507308 | Z255: =(SUM(D251:D254)*(0.995/4.005)-D254)/D254 -> 0.0027758273 | AA255: =(F255-F250)/F250 -> -0.021869302
A256: =WEEKNUM(C256,2) -> 2 | B256: =WEEKDAY(C256,2) -> 1 | C256: 39454 | D256: 1416.18 | E256: 1414.07 | F256: =AVERAGE(D252:D256) -> 1438.098 | G256: =AVERAGE(D247:D256) -> 1462.382 | H256: =(D256-D255)/D255 -> 0.0032232242 | I256: =(E256-D255)/D255 -> 0.0017284983 | J256: =H256-I256 -> 0.001494726 | K256: =(SUM(D252:D255)/4-D255)/D255 -> 0.022631639 | L256: =(SUM(D247:D255)/9-D255)/D255 -> 0.039589379 | M256: =(D256-F256)/F256 -> -0.015240964 | N256: =(D256-G256)/G256 -> -0.03159366 | O256: =(F256-G256)/D256 -> -0.017147538 | P256: =(D256-1468.36)/1468.36 -> -0.035536245 | T256: =(D256-D255)/D255 -> 0.0032232242 | U256: =(D256-D255)/D255 -> 0.0032232242 | V256: =(D251-D255)/D255 -> 0.047363686 | W256: =(D251*(1-0.01)-D255)/D255 -> 0.036890049 | X256: =(D256-D251)/D251 -> -0.04214435 | Y256: =(SUM(D252:D255)*(0.99/4.01)-D255)/D255 -> 0.0098806207 | Z256: =(SUM(D252:D255)*(0.995/4.005)-D255)/D255 -> 0.01624817 | AA256: =(F256-F251)/F251 -> -0.032669073
A257: =WEEKNUM(C257,2) -> 2 | B257: =WEEKDAY(C257,2) -> 2 | C257: 39455 | D257: 1390.19 | E257: 1415.71 | F257: =AVERAGE(D253:D257) -> 1422.464 | G257: =AVERAGE(D248:D257) -> 1452.955 | H257: =(D257-D256)/D256 -> -0.018352187 | I257: =(E257-D256)/D256 -> -0.00033187872 | J257: =H257-I257 -> -0.018020308 | K257: =(SUM(D253:D256)/4-D256)/D256 -> 0.010134658 | L257: =(SUM(D248:D256)/9-D256)/D256 -> 0.030892181 | M257: =(D257-F257)/F257 -> -0.022688799 | N257: =(D257-G257)/G257 -> -0.043198172 | O257: =(F257-G257)/D257 -> -0.021932973 | P257: =(D257-1468.36)/1468.36 -> -0.053236264 | T257: =(D257-D256)/D256 -> -0.018352187 | U257: =(D257-D256)/D256 -> -0.018352187 | V257: =(D252-D256)/D256 -> 0.036845599 | W257: =(D252*(1-0.01)-D256)/D256 -> 0.026477143 | X257: =(D257-D252)/D252 -> -0.053236264 | Y257: =(SUM(D253:D256)*(0.99/4.01)-D256)/D256 -> -0.0024605372 | Z257: =(SUM(D253:D256)*(0.995/4.005)-D256)/D256 -> 0.0038291982 | AA257: =(F257-F252)/F252 -> -0.041108338
A258: =WEEKNUM(C258,2) -> 2 | B258: =WEEKDAY(C258,2) -> 3 | C258: 39456 | D258: 1409.13 | E258: 1390.25 | F258: =AVERAGE(D254:D258) -> 1414.858 | G258: =AVERAGE(D249:D258) -> 1444.223 | H258: =(D258-D257)/D257 -> 0.013624037 | I258: =(E258-D257)/D257 -> 4.3159568e-05 | J258: =H258-I258 -> 0.013580877 | K258: =(SUM(D254:D257)/4-D257)/D257 -> 0.018774412 | L258: =(SUM(D249:D257)/9-D257)/D257 -> 0.041672162 | M258: =(D258-F258)/F258 -> -0.0040484628 | N258: =(D258-G258)/G258 -> -0.024298879 | O258: =(F258-G258)/D258 -> -0.020839099 | P258: =(D258-1468.36)/1468.36 -> -0.040337519 | T258: =(D258-D257)/D257 -> 0.013624037 | U258: =(D258-D257)/D257 -> 0.013624037 | V258: =(D253-D257)/D257 -> 0.04098001 | W258: =(D253*(1-0.01)-D257)/D257 -> 0.03057021 | X258: =(D258-D253)/D253 -> -0.026279057 | Y258: =(SUM(D254:D257)*(0.99/4.01)-D257)/D257 -> 0.0060714893 | Z258: =(SUM(D254:D257)*(0.995/4.005)-D257)/D257 -> 0.012415021 | AA258: =(F258-F253)/F253 -> -0.039855102
A259: =WEEKNUM(C259,2) -> 2 | B259: =WEEKDAY(C259,2) -> 4 | C259: 39457 | D259: 1420.33 | E259: 1406.78 | F259: =AVERAGE(D255:D259) -> 1409.492 | G259: =AVERAGE(D250:D259) -> 1436.49 | H259: =(D259-D258)/D258 -> 0.0079481666 | I259: =(E259-D258)/D258 -> -0.0016676957 | J259: =H259-I259 -> 0.0096158623 | K259: =(SUM(D255:D258)/4-D258)/D258 -> -0.0016659215 | L259: =(SUM(D250:D258)/9-D258)/D258 -> 0.020690465 | M259: =(D259-F259)/F259 -> 0.0076892952 | N259: =(D259-G259)/G259 -> -0.011249643 | O259: =(F259-G259)/D259 -> -0.019008259 | P259: =(D259-1468.36)/1468.36 -> -0.032709962 | T259: =(D259-D258)/D258 -> 0.0079481666 | U259: =(D259-D258)/D258 -> 0.0079481666 | V259: =(D254-D258)/D258 -> 0.026988284 | W259: =(D254*(1-0.01)-D258)/D258 -> 0.016718401 | X259: =(D259-D254)/D254 -> -0.018539761 | Y259: =(SUM(D255:D258)*(0.99/4.01)-D258)/D258 -> -0.014113977 | Z259: =(SUM(D255:D258)*(0.995/4.005)-D258)/D258 -> -0.0078977198 | AA259: =(F259-F254)/F254 -> -0.036895417
